{
 "cells": [
  {
   "cell_type": "code",
   "execution_count": 14,
   "id": "8f2c3782",
   "metadata": {},
   "outputs": [
    {
     "name": "stdout",
     "output_type": "stream",
     "text": [
      "Requirement already satisfied: konlpy in c:\\users\\cdl\\anaconda3\\lib\\site-packages (0.6.0)\n",
      "Requirement already satisfied: JPype1>=0.7.0 in c:\\users\\cdl\\anaconda3\\lib\\site-packages (from konlpy) (1.5.0)\n",
      "Requirement already satisfied: lxml>=4.1.0 in c:\\users\\cdl\\anaconda3\\lib\\site-packages (from konlpy) (4.8.0)\n",
      "Requirement already satisfied: numpy>=1.6 in c:\\users\\cdl\\anaconda3\\lib\\site-packages (from konlpy) (1.21.5)\n",
      "Requirement already satisfied: packaging in c:\\users\\cdl\\anaconda3\\lib\\site-packages (from JPype1>=0.7.0->konlpy) (21.3)\n",
      "Requirement already satisfied: pyparsing!=3.0.5,>=2.0.2 in c:\\users\\cdl\\anaconda3\\lib\\site-packages (from packaging->JPype1>=0.7.0->konlpy) (3.0.4)\n"
     ]
    }
   ],
   "source": [
    "import Preprocess"
   ]
  },
  {
   "cell_type": "code",
   "execution_count": 15,
   "id": "7cc8d1ef",
   "metadata": {},
   "outputs": [],
   "source": []
  },
  {
   "cell_type": "code",
   "execution_count": 18,
   "id": "1a5d6956",
   "metadata": {},
   "outputs": [
    {
     "ename": "TypeError",
     "evalue": "'module' object is not callable",
     "output_type": "error",
     "traceback": [
      "\u001b[1;31m---------------------------------------------------------------------------\u001b[0m",
      "\u001b[1;31mTypeError\u001b[0m                                 Traceback (most recent call last)",
      "Input \u001b[1;32mIn [18]\u001b[0m, in \u001b[0;36m<cell line: 1>\u001b[1;34m()\u001b[0m\n\u001b[1;32m----> 1\u001b[0m p \u001b[38;5;241m=\u001b[39m \u001b[43mPreprocess\u001b[49m\u001b[43m(\u001b[49m\u001b[43muserdic\u001b[49m\u001b[38;5;241;43m=\u001b[39;49m\u001b[38;5;124;43m'\u001b[39;49m\u001b[38;5;124;43m../utils/user_dic.tsv\u001b[39;49m\u001b[38;5;124;43m'\u001b[39;49m\u001b[43m)\u001b[49m\n",
      "\u001b[1;31mTypeError\u001b[0m: 'module' object is not callable"
     ]
    }
   ],
   "source": []
  },
  {
   "cell_type": "code",
   "execution_count": null,
   "id": "af823218",
   "metadata": {},
   "outputs": [],
   "source": []
  }
 ],
 "metadata": {
  "kernelspec": {
   "display_name": "Python 3 (ipykernel)",
   "language": "python",
   "name": "python3"
  },
  "language_info": {
   "codemirror_mode": {
    "name": "ipython",
    "version": 3
   },
   "file_extension": ".py",
   "mimetype": "text/x-python",
   "name": "python",
   "nbconvert_exporter": "python",
   "pygments_lexer": "ipython3",
   "version": "3.9.12"
  }
 },
 "nbformat": 4,
 "nbformat_minor": 5
}
